<?xml version="1.0" encoding="utf-8"?>
<sdf version="1.9">
	<model name="patasmonkey_model">
		<pose>0 0 0 0 0 0</pose>
		<link name="body_left:1">
			<pose>0.0 0.0 0.0 0.0 -0.0 0.0</pose>
			<inertial>
				<mass>5.977149333128697</mass>
				<pose>2.7075088848408945e-14 -0.07491905752363066 0.05992194832635813 -0.0 -0.0 -0.0</pose>
				<inertia>
					<ixx>0.018521735026712373</ixx>
					<ixy>-5.106774023738348e-15</ixy>
					<ixz>1.4632239957780798e-15</ixz>
					<iyy>0.05171445416669546</iyy>
					<iyz>-3.735988253558275e-05</iyz>
					<izz>0.05594377143878953</izz>
				</inertia>
			</inertial>
			<collision name="body_left:1_collision">
				<geometry>
					<mesh>
						<uri>model://patasmonkey_gazebo/meshes/body_left.stl</uri>
						<scale>0.001 0.001 0.001</scale>
					</mesh>
				</geometry>
			</collision>
			<visual name="body_left:1_visual">
				<geometry>
					<mesh>
						<uri>model://patasmonkey_gazebo/meshes/body_left.stl</uri>
						<scale>0.001 0.001 0.001</scale>
					</mesh>
				</geometry>
				<material>
					<ambient>1 0 0 1</ambient>    <!-- 赤色 -->
					<diffuse>1 0 0 1</diffuse>
					<specular>0.1 0.1 0.1 1</specular>
					<emissive>0 0 0 1</emissive>
				</material>
			</visual>
		</link>
		<link name="body_right:1">
			<pose>0.0 0.0 0.0 0.0 -0.0 0.0</pose>
			<inertial>
				<mass>5.933952434141838</mass>
				<pose>1.0817157499107769e-14 0.07546443954277501 0.05992138014009452 -0.0 -0.0 -0.0</pose>
				<inertia>
					<ixx>0.018269321974895048</ixx>
					<ixy>1.1848658946447257e-14</ixy>
					<ixz>-1.474498890486474e-15</ixz>
					<iyy>0.05170095487155976</iyy>
					<iyz>3.710544736609336e-05</iyz>
					<izz>0.05569135865378952</izz>
				</inertia>
			</inertial>
			<collision name="body_right:1_collision">
				<geometry>
					<mesh>
						<uri>model://patasmonkey_gazebo/meshes/body_right.stl</uri>
						<scale>0.001 0.001 0.001</scale>
					</mesh>
				</geometry>
			</collision>
			<visual name="body_right:1_visual">
				<geometry>
					<mesh>
						<uri>model://patasmonkey_gazebo/meshes/body_right.stl</uri>
						<scale>0.001 0.001 0.001</scale>
					</mesh>
				</geometry>
				<material>
					<ambient>1 0.2 0.2 1</ambient>    <!-- 赤色 -->
					<diffuse>1 0.2 0.2 1</diffuse>
					<specular>0.1 0.1 0.1 1</specular>
					<emissive>0 0 0 1</emissive>
				</material>
			</visual>
		</link>
		<link name="wheel_arm:1">
			<pose>-0.029999999999999964 -0.15999999999999998 0.029999999999999895 0.0 -0.3490658503988659 0.0</pose>
			<inertial>
				<mass>0.06867212404052492</mass>
				<pose>-0.08000000000035516 0.004999999999999989 3.469446951953614e-18 -0.0 0.3490658503988666 -0.0</pose>
				<inertia>
					<ixx>2.7839444321380923e-05</ixx>
					<ixy>0.0</ixy>
					<ixz>-4.773177745386561e-05</ixz>
					<iyy>0.00016830338776518633</iyy>
					<iyz>5.551115123125783e-21</iyz>
					<izz>0.0001416084788444838</izz>
				</inertia>
			</inertial>
			<collision name="wheel_arm:1_collision">
				<geometry>
					<mesh>
						<uri>model://patasmonkey_gazebo/meshes/wheel_arm.stl</uri>
						<scale>0.001 0.001 0.001</scale>
					</mesh>
				</geometry>
			</collision>
			<visual name="wheel_arm:1_visual">
				<geometry>
					<mesh>
						<uri>model://patasmonkey_gazebo/meshes/wheel_arm.stl</uri>
						<scale>0.001 0.001 0.001</scale>
					</mesh>
				</geometry>
				<material>
					<ambient>0 1 0 1</ambient>    <!-- 緑色 -->
					<diffuse>0 1 0 1</diffuse>
					<specular>0.1 0.1 0.1 1</specular>
					<emissive>0 0 0 1</emissive>
				</material>
			</visual>
		</link>
		<link name="wheel_arm:2">
			<pose>0.18035081932574515 -0.15999999999999998 -0.024723222932106985 0.0 0.3490658503988659 0.0</pose>
			<inertial>
				<mass>0.06867212404052492</mass>
				<pose>-0.08000000000035519 0.005000000000000011 -3.469446951953614e-18 -0.0 -0.3490658503988663 -0.0</pose>
				<inertia>
					<ixx>2.783944432138057e-05</ixx>
					<ixy>-1.7763568394002505e-19</ixy>
					<ixz>4.773177745386535e-05</ixz>
					<iyy>0.00016830338776518668</iyy>
					<iyz>0.0</iyz>
					<izz>0.0001416084788444831</izz>
				</inertia>
			</inertial>
			<collision name="wheel_arm:2_collision">
				<geometry>
					<mesh>
						<uri>model://patasmonkey_gazebo/meshes/wheel_arm.stl</uri>
						<scale>0.001 0.001 0.001</scale>
					</mesh>
				</geometry>
			</collision>
			<visual name="wheel_arm:2_visual">
				<geometry>
					<mesh>
						<uri>model://patasmonkey_gazebo/meshes/wheel_arm.stl</uri>
						<scale>0.001 0.001 0.001</scale>
					</mesh>
				</geometry>
				<material>
					<ambient>0 1 0 1</ambient>    <!-- 緑色 -->
					<diffuse>0 1 0 1</diffuse>
					<specular>0.1 0.1 0.1 1</specular>
					<emissive>0 0 0 1</emissive>
				</material>
			</visual>
		</link>
		<link name="wheel_arm:3">
			<pose>0.18035081932574498 0.14999999999999997 -0.02472322293210695 0.0 0.3490658503988659 0.0</pose>
			<inertial>
				<mass>0.06867212404052492</mass>
				<pose>-0.08000000000035515 0.004999999999999987 6.938893903907228e-18 -0.0 -0.3490658503988665 -0.0</pose>
				<inertia>
					<ixx>2.783944432138057e-05</ixx>
					<ixy>0.0</ixy>
					<ixz>4.773177745386559e-05</ixz>
					<iyy>0.00016830338776518633</iyy>
					<iyz>0.0</iyz>
					<izz>0.00014160847884448345</izz>
				</inertia>
			</inertial>
			<collision name="wheel_arm:3_collision">
				<geometry>
					<mesh>
						<uri>model://patasmonkey_gazebo/meshes/wheel_arm.stl</uri>
						<scale>0.001 0.001 0.001</scale>
					</mesh>
				</geometry>
			</collision>
			<visual name="wheel_arm:3_visual">
				<geometry>
					<mesh>
						<uri>model://patasmonkey_gazebo/meshes/wheel_arm.stl</uri>
						<scale>0.001 0.001 0.001</scale>
					</mesh>
				</geometry>
				<material>
					<ambient>0 1 0 1</ambient>    <!-- 緑色 -->
					<diffuse>0 1 0 1</diffuse>
					<specular>0.1 0.1 0.1 1</specular>
					<emissive>0 0 0 1</emissive>
				</material>
			</visual>
		</link>
		<link name="wheel_arm:4">
			<pose>-0.03 0.14999999999999997 0.03 0.0 -0.3490658503988659 0.0</pose>
			<inertial>
				<mass>0.06867212404052492</mass>
				<pose>-0.08000000000035518 0.005000000000000013 1.0408340855860843e-17 -0.0 0.3490658503988665 -0.0</pose>
				<inertia>
					<ixx>2.7839444321380214e-05</ixx>
					<ixy>-1.7763568394002505e-19</ixy>
					<ixz>-4.773177745386547e-05</ixz>
					<iyy>0.0001683033877651864</iyy>
					<iyz>5.551115123125783e-21</iyz>
					<izz>0.0001416084788444831</izz>
				</inertia>
			</inertial>
			<collision name="wheel_arm:4_collision">
				<geometry>
					<mesh>
						<uri>model://patasmonkey_gazebo/meshes/wheel_arm.stl</uri>
						<scale>0.001 0.001 0.001</scale>
					</mesh>
				</geometry>
			</collision>
			<visual name="wheel_arm:4_visual">
				<geometry>
					<mesh>
						<uri>model://patasmonkey_gazebo/meshes/wheel_arm.stl</uri>
						<scale>0.001 0.001 0.001</scale>
					</mesh>
				</geometry>
				<material>
					<ambient>0 1 0 1</ambient>    <!-- 緑色 -->
					<diffuse>0 1 0 1</diffuse>
					<specular>0.1 0.1 0.1 1</specular>
					<emissive>0 0 0 1</emissive>
				</material>
			</visual>
		</link>
		<link name="wheel:1">
			<pose>-0.18035081932574493 -0.20999999999999985 -0.024723222932107065 0.0 -0.34906585039886656 0.0</pose>
			<inertial>
				<mass>0.6459736269326636</mass>
				<pose>-9.434532378258817e-14 0.024999999999999967 -9.371267768204583e-17 -0.0 0.3490658503988666 -0.0</pose>
				<inertia>
					<ixx>0.0020372715927300987</ixx>
					<ixy>-2.842170943040401e-18</ixy>
					<ixz>1.815529060422705e-13</ixz>
					<iyy>0.0038053875071388916</iyy>
					<iyz>-7.105427357601002e-19</iyz>
					<izz>0.002037271592297401</izz>
				</inertia>
			</inertial>
			<collision name="wheel:1_collision">
				<geometry>
					<mesh>
						<uri>model://patasmonkey_gazebo/meshes/wheel.stl</uri>
						<scale>0.001 0.001 0.001</scale>
					</mesh>
				</geometry>
			</collision>
			<visual name="wheel:1_visual">
				<geometry>
					<mesh>
						<uri>model://patasmonkey_gazebo/meshes/wheel.stl</uri>
						<scale>0.001 0.001 0.001</scale>
					</mesh>
				</geometry>
				<material>
					<ambient>0 0 1 1</ambient>    <!-- 青色 -->
					<diffuse>0 0 1 1</diffuse>
					<specular>0.1 0.1 0.1 1</specular>
					<emissive>0 0 0 1</emissive>
				</material>
			</visual>
		</link>
		<link name="wheel:2">
			<pose>0.18035081932574523 -0.20999999999999985 -0.02472322293210703 0.0 0.3490658503988664 0.0</pose>
			<inertial>
				<mass>0.6459736269326636</mass>
				<pose>-9.433815616458313e-14 0.024999999999999967 -8.828393916616693e-17 -0.0 -0.3490658503988664 -0.0</pose>
				<inertia>
					<ixx>0.002037271592730113</ixx>
					<ixy>-2.842170943040401e-18</ixy>
					<ixz>-1.8153585301661223e-13</ixz>
					<iyy>0.0038053875071388916</iyy>
					<iyz>-3.552713678800501e-19</iyz>
					<izz>0.0020372715922973897</izz>
				</inertia>
			</inertial>
			<collision name="wheel:2_collision">
				<geometry>
					<mesh>
						<uri>model://patasmonkey_gazebo/meshes/wheel.stl</uri>
						<scale>0.001 0.001 0.001</scale>
					</mesh>
				</geometry>
			</collision>
			<visual name="wheel:2_visual">
				<geometry>
					<mesh>
						<uri>model://patasmonkey_gazebo/meshes/wheel.stl</uri>
						<scale>0.001 0.001 0.001</scale>
					</mesh>
				</geometry>
				<material>
					<ambient>0 0 1 1</ambient>    <!-- 青色 -->
					<diffuse>0 0 1 1</diffuse>
					<specular>0.1 0.1 0.1 1</specular>
					<emissive>0 0 0 1</emissive>
				</material>
			</visual>
		</link>
		<link name="wheel:3">
			<pose>0.18035081932574534 0.15999999999999992 -0.02472322293210699 0.0 0.3490658503988659 0.0</pose>
			<inertial>
				<mass>0.6459736269326636</mass>
				<pose>-9.433815616458314e-14 0.024999999999999967 -8.828393916612275e-17 -0.0 -0.3490658503988659 -0.0</pose>
				<inertia>
					<ixx>0.002037271592730113</ixx>
					<ixy>-2.842170943040401e-18</ixy>
					<ixz>-1.8153585301661223e-13</ixz>
					<iyy>0.0038053875071388916</iyy>
					<iyz>0.0</iyz>
					<izz>0.0020372715922973897</izz>
				</inertia>
			</inertial>
			<collision name="wheel:3_collision">
				<geometry>
					<mesh>
						<uri>model://patasmonkey_gazebo/meshes/wheel.stl</uri>
						<scale>0.001 0.001 0.001</scale>
					</mesh>
				</geometry>
			</collision>
			<visual name="wheel:3_visual">
				<geometry>
					<mesh>
						<uri>model://patasmonkey_gazebo/meshes/wheel.stl</uri>
						<scale>0.001 0.001 0.001</scale>
					</mesh>
				</geometry>
				<material>
					<ambient>0 0 1 1</ambient>    <!-- 青色 -->
					<diffuse>0 0 1 1</diffuse>
					<specular>0.1 0.1 0.1 1</specular>
					<emissive>0 0 0 1</emissive>
				</material>
			</visual>
		</link>
		<link name="wheel:4">
			<pose>-0.18035081932574537 0.15999999999999995 -0.024723222932106995 0.0 -0.3490658503988659 0.0</pose>
			<inertial>
				<mass>0.6459736269326636</mass>
				<pose>-9.437140549217987e-14 0.024999999999999994 -8.421971173196982e-17 -0.0 0.3490658503988659 -0.0</pose>
				<inertia>
					<ixx>0.0020372715927301018</ixx>
					<ixy>-2.842170943040401e-18</ixy>
					<ixz>1.815525507709026e-13</ixz>
					<iyy>0.0038053875071388916</iyy>
					<iyz>-7.105427357601002e-19</iyz>
					<izz>0.002037271592297401</izz>
				</inertia>
			</inertial>
			<collision name="wheel:4_collision">
				<geometry>
					<mesh>
						<uri>model://patasmonkey_gazebo/meshes/wheel.stl</uri>
						<scale>0.001 0.001 0.001</scale>
					</mesh>
				</geometry>
			</collision>
			<visual name="wheel:4_visual">
				<geometry>
					<mesh>
						<uri>model://patasmonkey_gazebo/meshes/wheel.stl</uri>
						<scale>0.001 0.001 0.001</scale>
					</mesh>
				</geometry>
				<material>
					<ambient>0 0 1 1</ambient>    <!-- 青色 -->
					<diffuse>0 0 1 1</diffuse>
					<specular>0.1 0.1 0.1 1</specular>
					<emissive>0 0 0 1</emissive>
				</material>
			</visual>
		</link>
		<joint type="revolute" name="rev0">
			<pose>0.0 0.01 0.06 -0.0 -0.0 -0.0</pose>
			<child>body_right:1</child>
			<parent>body_left:1</parent>
			<axis>
				<xyz>0.0 1.0 0.0</xyz>
				<dynamics>
					<spring_stiffness>5.0</spring_stiffness>
      				<spring_reference>0</spring_reference>
					<damping>2.0</damping>
				</dynamics>
			</axis>
		</joint>
		<joint type="revolute" name="rev1">
			<pose>0.0 0.010000000000000005 0.0 -0.0 0.3490658503988666 -0.0</pose>
			<child>wheel_arm:1</child>
			<parent>body_left:1</parent>
			<axis>
				<xyz>0.0 1.0 0.0</xyz>
				<dynamics>
					<spring_stiffness>25.0</spring_stiffness>
      				<spring_reference>0</spring_reference>
					<damping>1.5</damping>
				</dynamics>
			</axis>
		</joint>
		<joint type="revolute" name="rev2">
			<pose>-0.15999999999999998 0.009999999999999995 6.938893903907228e-18 -0.0 -0.3490658503988663 -0.0</pose>
			<child>wheel_arm:2</child>
			<parent>body_left:1</parent>
			<axis>
				<xyz>0.0 1.0 0.0</xyz>
				<dynamics>
					<spring_stiffness>25.0</spring_stiffness>
      				<spring_reference>0</spring_reference>
					<damping>1.5</damping>
				</dynamics>
			</axis>
		</joint>
		<joint type="revolute" name="rev3">
			<pose>-0.16000000000000003 0.0 -6.938893903907228e-18 -0.0 -0.3490658503988665 -0.0</pose>
			<child>wheel_arm:3</child>
			<parent>body_right:1</parent>
			<axis>
				<xyz>0.0 -1.0 0.0</xyz>
				<dynamics>
					<spring_stiffness>25.0</spring_stiffness>
      				<spring_reference>0</spring_reference>
					<damping>1.5</damping>
				</dynamics>
			</axis>
		</joint>
		<joint type="revolute" name="rev4">
			<pose>2.3732414875359672e-18 0.0 6.520427397917945e-18 -0.0 0.3490658503988665 -0.0</pose>
			<child>wheel_arm:4</child>
			<parent>body_right:1</parent>
			<axis>
				<xyz>0.0 -1.0 0.0</xyz>
				<dynamics>
					<spring_stiffness>25.0</spring_stiffness>
      				<spring_reference>0</spring_reference>
					<damping>0.5</damping>
				</dynamics>
			</axis>
		</joint>
		<joint type="revolute" name="rev5">
			<pose>1.1866207437679817e-18 0.04999999999999999 3.260213698958972e-18 -0.0 0.3490658503988666 -0.0</pose>
			<child>wheel:1</child>
			<parent>wheel_arm:1</parent>
			<axis>
				<xyz>0.0 -0.9999999999999978 0.0</xyz>
			</axis>
		</joint>
		<joint type="revolute" name="rev6">
			<pose>0.0 0.04999999999999999 0.0 -0.0 -0.3490658503988664 -0.0</pose>
			<child>wheel:2</child>
			<parent>wheel_arm:2</parent>
			<axis>
				<xyz>0.0 -0.9999999999999987 0.0</xyz>
			</axis>
		</joint>
		<joint type="revolute" name="rev7">
			<pose>0.0 0.0 0.0 -0.0 -0.3490658503988659 -0.0</pose>
			<child>wheel:3</child>
			<parent>wheel_arm:3</parent>
			<axis>
				<xyz>0.0 -0.9999999999999981 0.0</xyz>
			</axis>
		</joint>
		<joint type="revolute" name="rev8">
			<pose>0.0 0.0 0.0 -0.0 0.3490658503988659 -0.0</pose>
			<child>wheel:4</child>
			<parent>wheel_arm:4</parent>
			<axis>
				<xyz>0.0 -0.9999999999999982 0.0</xyz>
			</axis>
		</joint>
	</model>
</sdf>
